Traceback (most recent call last):
  File "/home/albertor/anaconda3/envs/jupyter/lib/python3.7/site-packages/jupyter_cache/executors/utils.py", line 56, in single_nb_execution
    record_timing=False,
  File "/home/albertor/anaconda3/envs/jupyter/lib/python3.7/site-packages/nbclient/client.py", line 1204, in execute
    return NotebookClient(nb=nb, resources=resources, km=km, **kwargs).execute()
  File "/home/albertor/anaconda3/envs/jupyter/lib/python3.7/site-packages/nbclient/util.py", line 84, in wrapped
    return just_run(coro(*args, **kwargs))
  File "/home/albertor/anaconda3/envs/jupyter/lib/python3.7/site-packages/nbclient/util.py", line 62, in just_run
    return loop.run_until_complete(coro)
  File "/home/albertor/anaconda3/envs/jupyter/lib/python3.7/asyncio/base_events.py", line 583, in run_until_complete
    return future.result()
  File "/home/albertor/anaconda3/envs/jupyter/lib/python3.7/site-packages/nbclient/client.py", line 664, in async_execute
    cell, index, execution_count=self.code_cells_executed + 1
  File "/home/albertor/anaconda3/envs/jupyter/lib/python3.7/site-packages/nbclient/client.py", line 965, in async_execute_cell
    await self._check_raise_for_error(cell, cell_index, exec_reply)
  File "/home/albertor/anaconda3/envs/jupyter/lib/python3.7/site-packages/nbclient/client.py", line 862, in _check_raise_for_error
    raise CellExecutionError.from_cell_and_msg(cell, exec_reply_content)
nbclient.exceptions.CellExecutionError: An error occurred while executing the following cell:
------------------
latest = data['synchronized'][data['synchronized'].index >= (dt.datetime.today() - dt.timedelta(days=30))]
#print('Zoom on the last 30 days')
plot_stats_logs_daily(latest, plot_max=False)
------------------

[0;31m---------------------------------------------------------------------------[0m
[0;31mValueError[0m                                Traceback (most recent call last)
[0;32m/tmp/ipykernel_75007/3276077045.py[0m in [0;36m<module>[0;34m[0m
[1;32m      1[0m [0mlatest[0m [0;34m=[0m [0mdata[0m[0;34m[[0m[0;34m'synchronized'[0m[0;34m][0m[0;34m[[0m[0mdata[0m[0;34m[[0m[0;34m'synchronized'[0m[0;34m][0m[0;34m.[0m[0mindex[0m [0;34m>=[0m [0;34m([0m[0mdt[0m[0;34m.[0m[0mdatetime[0m[0;34m.[0m[0mtoday[0m[0;34m([0m[0;34m)[0m [0;34m-[0m [0mdt[0m[0;34m.[0m[0mtimedelta[0m[0;34m([0m[0mdays[0m[0;34m=[0m[0;36m30[0m[0;34m)[0m[0;34m)[0m[0;34m][0m[0;34m[0m[0;34m[0m[0m
[1;32m      2[0m [0;31m#print('Zoom on the last 30 days')[0m[0;34m[0m[0;34m[0m[0;34m[0m[0m
[0;32m----> 3[0;31m [0mplot_stats_logs_daily[0m[0;34m([0m[0mlatest[0m[0;34m,[0m [0mplot_max[0m[0;34m=[0m[0;32mFalse[0m[0;34m)[0m[0;34m[0m[0;34m[0m[0m
[0m
[0;32m/tmp/ipykernel_75007/3276914466.py[0m in [0;36mplot_stats_logs_daily[0;34m(synchronized, deleted, fscanner, plot_max)[0m
[1;32m      2[0m [0;34m[0m[0m
[1;32m      3[0m     [0;31m# Simple stats that will be annotations on the plot[0m[0;34m[0m[0;34m[0m[0;34m[0m[0m
[0;32m----> 4[0;31m     [0mmedian[0m [0;34m=[0m [0mint[0m[0;34m([0m[0msynchronized[0m[0;34m[[0m[0;34m'number'[0m[0;34m][0m[0;34m.[0m[0miloc[0m[0;34m[[0m[0;36m0[0m[0;34m:[0m[0;34m-[0m[0;36m2[0m[0;34m][0m[0;34m.[0m[0mmedian[0m[0;34m([0m[0;34m)[0m[0;34m)[0m[0;34m[0m[0;34m[0m[0m
[0m[1;32m      5[0m     [0mlast[0m [0;34m=[0m [0mint[0m[0;34m([0m[0msynchronized[0m[0;34m[[0m[0;34m'number'[0m[0;34m][0m[0;34m.[0m[0miloc[0m[0;34m[[0m[0;34m-[0m[0;36m1[0m[0;34m][0m[0;34m)[0m[0;34m[0m[0;34m[0m[0m
[1;32m      6[0m     [0mt_median[0m [0;34m=[0m [0msynchronized[0m[0;34m[[0m[0;34m'timeliness'[0m[0;34m][0m[0;34m.[0m[0miloc[0m[0;34m[[0m[0;36m0[0m[0;34m:[0m[0;34m-[0m[0;36m2[0m[0;34m][0m[0;34m.[0m[0mmedian[0m[0;34m([0m[0;34m)[0m[0;34m[0m[0;34m[0m[0m

[0;31mValueError[0m: cannot convert float NaN to integer
ValueError: cannot convert float NaN to integer

