Traceback (most recent call last):
  File "/home/lukem/anaconda3/lib/python3.11/site-packages/jupyter_cache/executors/utils.py", line 58, in single_nb_execution
    executenb(
  File "/home/lukem/anaconda3/lib/python3.11/site-packages/nbclient/client.py", line 1305, in execute
    return NotebookClient(nb=nb, resources=resources, km=km, **kwargs).execute()
           ^^^^^^^^^^^^^^^^^^^^^^^^^^^^^^^^^^^^^^^^^^^^^^^^^^^^^^^^^^^^^^^^^^^^^
  File "/home/lukem/anaconda3/lib/python3.11/site-packages/jupyter_core/utils/__init__.py", line 173, in wrapped
    return loop.run_until_complete(inner)
           ^^^^^^^^^^^^^^^^^^^^^^^^^^^^^^
  File "/home/lukem/anaconda3/lib/python3.11/asyncio/base_events.py", line 653, in run_until_complete
    return future.result()
           ^^^^^^^^^^^^^^^
  File "/home/lukem/anaconda3/lib/python3.11/site-packages/nbclient/client.py", line 705, in async_execute
    await self.async_execute_cell(
  File "/home/lukem/anaconda3/lib/python3.11/site-packages/nbclient/client.py", line 1058, in async_execute_cell
    await self._check_raise_for_error(cell, cell_index, exec_reply)
  File "/home/lukem/anaconda3/lib/python3.11/site-packages/nbclient/client.py", line 914, in _check_raise_for_error
    raise CellExecutionError.from_cell_and_msg(cell, exec_reply_content)
nbclient.exceptions.CellExecutionError: An error occurred while executing the following cell:
------------------
data = read_dhus_logs(csvdir / 'S2L2A-backend-AOI_inputs.csv')
plot_stats_logs(data['synchronized'], plot_max=True)
------------------


[0;31m---------------------------------------------------------------------------[0m
[0;31mTypeError[0m                                 Traceback (most recent call last)
Cell [0;32mIn[21], line 1[0m
[0;32m----> 1[0m data [38;5;241m=[39m read_dhus_logs(csvdir [38;5;241m/[39m [38;5;124m'[39m[38;5;124mS2L2A-backend-AOI_inputs.csv[39m[38;5;124m'[39m)
[1;32m      2[0m plot_stats_logs(data[[38;5;124m'[39m[38;5;124msynchronized[39m[38;5;124m'[39m], plot_max[38;5;241m=[39m[38;5;28;01mTrue[39;00m)

Cell [0;32mIn[15], line 6[0m, in [0;36mread_dhus_logs[0;34m(file)[0m
[1;32m      4[0m out [38;5;241m=[39m {}
[1;32m      5[0m [38;5;28;01mfor[39;00m [38;5;28mtype[39m [38;5;129;01min[39;00m [[38;5;124m'[39m[38;5;124msynchronized[39m[38;5;124m'[39m, [38;5;124m'[39m[38;5;124mdeleted[39m[38;5;124m'[39m, [38;5;124m'[39m[38;5;124mfscanner[39m[38;5;124m'[39m]:
[0;32m----> 6[0m     d [38;5;241m=[39m data[data[[38;5;124m'[39m[38;5;124maction[39m[38;5;124m'[39m] [38;5;241m==[39m [38;5;28mtype[39m][38;5;241m.[39mdrop([38;5;124m'[39m[38;5;124maction[39m[38;5;124m'[39m, [38;5;241m1[39m)
[1;32m      7[0m     stats_1 [38;5;241m=[39m d[38;5;241m.[39mgroupby([[38;5;124m'[39m[38;5;124mday[39m[38;5;124m'[39m])[38;5;241m.[39msum()[[[38;5;124m'[39m[38;5;124msize[39m[38;5;124m'[39m, [38;5;124m'[39m[38;5;124mnumber[39m[38;5;124m'[39m]]
[1;32m      8[0m     stats_2 [38;5;241m=[39m d[38;5;241m.[39mgroupby([[38;5;124m'[39m[38;5;124mday[39m[38;5;124m'[39m])[38;5;241m.[39mmedian()[[38;5;124m'[39m[38;5;124mtimeliness[39m[38;5;124m'[39m]

[0;31mTypeError[0m: DataFrame.drop() takes from 1 to 2 positional arguments but 3 were given

