Traceback (most recent call last):
  File "/home/lukem/anaconda3/lib/python3.11/site-packages/jupyter_cache/executors/utils.py", line 58, in single_nb_execution
    executenb(
  File "/home/lukem/anaconda3/lib/python3.11/site-packages/nbclient/client.py", line 1305, in execute
    return NotebookClient(nb=nb, resources=resources, km=km, **kwargs).execute()
           ^^^^^^^^^^^^^^^^^^^^^^^^^^^^^^^^^^^^^^^^^^^^^^^^^^^^^^^^^^^^^^^^^^^^^
  File "/home/lukem/anaconda3/lib/python3.11/site-packages/jupyter_core/utils/__init__.py", line 173, in wrapped
    return loop.run_until_complete(inner)
           ^^^^^^^^^^^^^^^^^^^^^^^^^^^^^^
  File "/home/lukem/anaconda3/lib/python3.11/asyncio/base_events.py", line 653, in run_until_complete
    return future.result()
           ^^^^^^^^^^^^^^^
  File "/home/lukem/anaconda3/lib/python3.11/site-packages/nbclient/client.py", line 705, in async_execute
    await self.async_execute_cell(
  File "/home/lukem/anaconda3/lib/python3.11/site-packages/nbclient/client.py", line 1058, in async_execute_cell
    await self._check_raise_for_error(cell, cell_index, exec_reply)
  File "/home/lukem/anaconda3/lib/python3.11/site-packages/nbclient/client.py", line 914, in _check_raise_for_error
    raise CellExecutionError.from_cell_and_msg(cell, exec_reply_content)
nbclient.exceptions.CellExecutionError: An error occurred while executing the following cell:
------------------
data_s1 = read_dhus_logs_details(logsdir / 'S1-backend-AOI_inputs.csv')
data_s2l1c = read_dhus_logs_details(logsdir / 'S2L1C-backend-AOI_inputs.csv')
data_s2l2a = read_dhus_logs_details(logsdir / 'S2L2A-backend-AOI_inputs.csv')
data_s3 = read_dhus_logs_details(logsdir / 'S3-backend-AOI_inputs.csv')
#data_s2dterr = read_dhus_logs_details(logsdir / 'S2DEM-backend-global_inputs.csv')
data_s5 = read_dhus_logs_details(logsdir / 'S5p-backend-AOI_inputs.csv')
all_colhub = data_s1.append(data_s2l1c).append(data_s2l2a).append(data_s3).append(data_s5)
------------------


[0;31m---------------------------------------------------------------------------[0m
[0;31mAttributeError[0m                            Traceback (most recent call last)
[0;32m/tmp/ipykernel_80062/4105924330.py[0m in [0;36m?[0;34m()[0m
[1;32m      3[0m [0mdata_s2l2a[0m [0;34m=[0m [0mread_dhus_logs_details[0m[0;34m([0m[0mlogsdir[0m [0;34m/[0m [0;34m'S2L2A-backend-AOI_inputs.csv'[0m[0;34m)[0m[0;34m[0m[0;34m[0m[0m
[1;32m      4[0m [0mdata_s3[0m [0;34m=[0m [0mread_dhus_logs_details[0m[0;34m([0m[0mlogsdir[0m [0;34m/[0m [0;34m'S3-backend-AOI_inputs.csv'[0m[0;34m)[0m[0;34m[0m[0;34m[0m[0m
[1;32m      5[0m [0;31m#data_s2dterr = read_dhus_logs_details(logsdir / 'S2DEM-backend-global_inputs.csv')[0m[0;34m[0m[0;34m[0m[0m
[1;32m      6[0m [0mdata_s5[0m [0;34m=[0m [0mread_dhus_logs_details[0m[0;34m([0m[0mlogsdir[0m [0;34m/[0m [0;34m'S5p-backend-AOI_inputs.csv'[0m[0;34m)[0m[0;34m[0m[0;34m[0m[0m
[0;32m----> 7[0;31m [0mall_colhub[0m [0;34m=[0m [0mdata_s1[0m[0;34m.[0m[0mappend[0m[0;34m([0m[0mdata_s2l1c[0m[0;34m)[0m[0;34m.[0m[0mappend[0m[0;34m([0m[0mdata_s2l2a[0m[0;34m)[0m[0;34m.[0m[0mappend[0m[0;34m([0m[0mdata_s3[0m[0;34m)[0m[0;34m.[0m[0mappend[0m[0;34m([0m[0mdata_s5[0m[0;34m)[0m[0;34m[0m[0;34m[0m[0m
[0m
[0;32m~/anaconda3/lib/python3.11/site-packages/pandas/core/generic.py[0m in [0;36m?[0;34m(self, name)[0m
[1;32m   6200[0m             [0;32mand[0m [0mname[0m [0;32mnot[0m [0;32min[0m [0mself[0m[0;34m.[0m[0m_accessors[0m[0;34m[0m[0;34m[0m[0m
[1;32m   6201[0m             [0;32mand[0m [0mself[0m[0;34m.[0m[0m_info_axis[0m[0;34m.[0m[0m_can_hold_identifiers_and_holds_name[0m[0;34m([0m[0mname[0m[0;34m)[0m[0;34m[0m[0;34m[0m[0m
[1;32m   6202[0m         ):
[1;32m   6203[0m             [0;32mreturn[0m [0mself[0m[0;34m[[0m[0mname[0m[0;34m][0m[0;34m[0m[0;34m[0m[0m
[0;32m-> 6204[0;31m         [0;32mreturn[0m [0mobject[0m[0;34m.[0m[0m__getattribute__[0m[0;34m([0m[0mself[0m[0;34m,[0m [0mname[0m[0;34m)[0m[0;34m[0m[0;34m[0m[0m
[0m
[0;31mAttributeError[0m: 'DataFrame' object has no attribute 'append'

